Workbook

Sheet Registration
A1: registration_number | B1: commercial_name | C1: common_name | D1: concentration | E1: formula_type | F1: origin | G1: applicant | H1: importer | I1: distributor | J1: issue_date | K1: expiry_date | L1: category | M1: moa_group
A2: 3 - 2554 | B2: เรนโบว 2.5 โอดี (Rainbow 2.5 OD) | C2: penoxsulam | D2: 2.5%W/V | E2: OD | F2: PT. Corteva Agriscience Manufacturing Indonesia, Indonesia | G2: ดาว อะโกรไซแอนส์ (ประเทศไทย) บจก. | H2: ดาว อะโกรไซแอนส์ (ประเทศไทย) บจก. | I2: คอร์เทวา อะกริไซเอนซ์ (ประเทศไทย) บจก. | J2: 07/04/2023 | K2: 06/04/2029 | L2: =IFERROR(_xlfn.XLOOKUP($C2,'Pesticide Types'!$A$2:$A$519,'Pesticide Types'!$B$2:$B$519),"Unclassified") -> Herbicide | M2: =IFERROR(_xlfn.XLOOKUP($C2,'Pesticide Types'!$A$2:$A$519,'Pesticide Types'!$D$2:$D$519),"None") -> HRAC 2
A3: 7 - 2554 | B3: พรีวาธอน (Prevathon) | C3: chlorantraniliprole | D3: 5.17%W/V | E3: SC | F3: FMC Agro Singapore Pte. Ltd., Singapore; FMC Vietnam Company Limited, Vietnam; PT FMC Agricultural Manufacturing, Indonesia; PT Bina Guna Kimia, Indonesia; Cheminova Deutschland GmbH & Co. KG, Germany | G3: เอฟเอ็ม ซี เอจี (ประเทศไทย) | H3: เอฟเอ็ม ซี เอจี (ประเทศไทย) | I3: เอฟเอ็ม ซี เอจี (ประเทศไทย) บจก. | J3: 07/04/2023 | K3: 06/04/2029 | L3: =IFERROR(_xlfn.XLOOKUP($C3,'Pesticide Types'!$A$2:$A$519,'Pesticide Types'!$B$2:$B$519),"Unclassified") -> Insecticide | M3: =IFERROR(_xlfn.XLOOKUP($C3,'Pesticide Types'!$A$2:$A$519,'Pesticide Types'!$D$2:$D$519),"None") -> IRAC 28
A4: 8 - 2554 | B4: อิมแพค (Impact) | C4: flutriafol | D4: 12.5%W/V | E4: SC | F4: FMC Quimica do Brasil Ltda., Brazil | G4: โซตัส อินเตอร์เนชั่นแนล บจก. | H4: โซตัส อินเตอร์เนชั่นแนล บจก. | I4: โซตัส อินเตอร์เนชั่นแนล บจก. | J4: 07/04/2023 | K4: 06/04/2029 | L4: =IFERROR(_xlfn.XLOOKUP($C4,'Pesticide Types'!$A$2:$A$519,'Pesticide Types'!$B$2:$B$519),"Unclassified") -> Fungicide | M4: =IFERROR(_xlfn.XLOOKUP($C4,'Pesticide Types'!$A$2:$A$519,'Pesticide Types'!$D$2:$D$519),"None") -> FRAC 3
A5: 9 - 2554 | B5: แอคเซ็บท์ 60 โอดี (Accept 60 OD) | C5: cyhalofop-butyl+penoxsulam | D5: 5%+1%W/V | E5: OD | F5: PT. Corteva Agriscience Manufacturing Indonesia, Indonesia | G5: คอร์เทวา อะกริไซเอนซ์ (ประเทศไทย) บจก. | H5: คอร์เทวา อะกริไซเอนซ์ (ประเทศไทย) บจก. | I5: คอร์เทวา อะกริไซเอนซ์ (ประเทศไทย) บจก. | J5: 20/04/2023 | K5: 19/04/2029 | L5: =IFERROR(_xlfn.XLOOKUP($C5,'Pesticide Types'!$A$2:$A$519,'Pesticide Types'!$B$2:$B$519),"Unclassified") -> Unclassified | M5: =IFERROR(_xlfn.XLOOKUP($C5,'Pesticide Types'!$A$2:$A$519,'Pesticide Types'!$D$2:$D$519),"None") -> None
A6: 10 - 2554 | B6: ดูอัล โกลด์ (Dual Gold) | C6: s-metolachlor | D6: 96%W/V | E6: EC | F6: Syngenta Production France S.A.S., France; Chemark ZRT., Hungary; Syngenta (Suzhou) Crop Protection Co., Ltd. PRC | G6: ซินเจนทา ครอป โปรเทคชั่น บจก. | H6: ซินเจนทา ครอป โปรเทคชั่น บจก. | I6: ซินเจนทา ครอป โปรเทคชั่น บจก. | J6: 02/05/2023 | K6: 01/05/2029 | L6: =IFERROR(_xlfn.XLOOKUP($C6,'Pesticide Types'!$A$2:$A$519,'Pesticide Types'!$B$2:$B$519),"Unclassified") -> Herbicide | M6: =IFERROR(_xlfn.XLOOKUP($C6,'Pesticide Types'!$A$2:$A$519,'Pesticide Types'!$D$2:$D$519),"None") -> HRAC 15
A7: 13 - 2554 | B7: บาติไซด์ 16000 เอสซี (BATICIDE 16000 SC) | C7: bacillus thuringiensis berliner subsp. aizawai | D7: 1.15 x 1010 cfu/ml (16,000 IU/mg SC) | E7: SC | F7: King Biotec Corp Co., Ltd. PRC | G7: ไอ ซี พี ลัดดา บจก. | H7: ไอ ซี พี ลัดดา บจก. | I7: ไอ ซี พี ลัดดา บจก. | J7: 27/05/2023 | K7: 26/05/2029 | L7: =IFERROR(_xlfn.XLOOKUP($C7,'Pesticide Types'!$A$2:$A$519,'Pesticide Types'!$B$2:$B$519),"Unclassified") -> Insecticide | M7: =IFERROR(_xlfn.XLOOKUP($C7,'Pesticide Types'!$A$2:$A$519,'Pesticide Types'!$D$2:$D$519),"None") -> IRAC 11A
A8: 19 - 2554 | B8: อมิสตา (Amistar) | C8: azoxystrobin | D8: 25%W/V | E8: SC | F8: Syngenta Limited, UK; Syngenta Production France S.A.S., France | G8: ซินเจนทา ครอป โปรเทคชั่น บจก. | H8: ซินเจนทา ครอป โปรเทคชั่น บจก. | I8: ซินเจนทา ครอป โปรเทคชั่น บจก. | J8: 05/07/2023 | K8: 04/07/2029 | L8: =IFERROR(_xlfn.XLOOKUP($C8,'Pesticide Types'!$A$2:$A$519,'Pesticide Types'!$B$2:$B$519),"Unclassified") -> Fungicide | M8: =IFERROR(_xlfn.XLOOKUP($C8,'Pesticide Types'!$A$2:$A$519,'Pesticide Types'!$D$2:$D$519),"None") -> FRAC 11
A9: 20 - 2554 | B9: อมิสตา | C9: azoxystrobin | D9: 25%W/V | E9: SC | F9: Syngenta Limited, UK; Syngenta Production France S.A.S., France | G9: ซินเจนทา ครอป โปรเทคชั่น บจก. | H9: ซินเจนทา ครอป โปรเทคชั่น บจก. | I9: ซินเจนทา ครอป โปรเทคชั่น บจก. | J9: 05/07/2023 | K9: 04/07/2029 | L9: =IFERROR(_xlfn.XLOOKUP($C9,'Pesticide Types'!$A$2:$A$519,'Pesticide Types'!$B$2:$B$519),"Unclassified") -> Fungicide | M9: =IFERROR(_xlfn.XLOOKUP($C9,'Pesticide Types'!$A$2:$A$519,'Pesticide Types'!$D$2:$D$519),"None") -> FRAC 11
A10: 23 - 2554 | B10: ไพน์ ฟอส (Pine Fos) | C10: phosphonic acid | D10: 40%W/V | E10: SL | F10: Liquid Fertiliser Pty. Ltd., Australia | G10: ออสก้าร์ อะโกร บจก. | H10: ออสก้าร์ อะโกร บจก. | I10: ออสก้าร์ อะโกร บจก. | J10: 26/07/2023 | K10: 25/07/2029 | L10: =IFERROR(_xlfn.XLOOKUP($C10,'Pesticide Types'!$A$2:$A$519,'Pesticide Types'!$B$2:$B$519),"Unclassified") -> Fungicide | M10: =IFERROR(_xlfn.XLOOKUP($C10,'Pesticide Types'!$A$2:$A$519,'Pesticide Types'!$D$2:$D$519),"None") -> FRAC P07
A11: 58 - 2554 | B11: อาเทีย (Artea) | C11: cyproconazole+propiconazole | D11: 8%+25%W/V | E11: EC | F11: Syngenta Vietnam Ltd., Vietnam | G11: ซินเจนทา ครอป โปรเทคชั่น บจก. | H11: ซินเจนทา ครอป โปรเทคชั่น บจก. | I11: ซินเจนทา ครอป โปรเทคชั่น บจก. | J11: 30/08/2023 | K11: 29/08/2029 | L11: =IFERROR(_xlfn.XLOOKUP($C11,'Pesticide Types'!$A$2:$A$519,'Pesticide Types'!$B$2:$B$519),"Unclassified") -> Unclassified | M11: =IFERROR(_xlfn.XLOOKUP($C11,'Pesticide Types'!$A$2:$A$519,'Pesticide Types'!$D$2:$D$519),"None") -> None
A12: 68 - 2554 | B12: คาโอ-จิน (CAO-JIN) | C12: pendimethalin | D12: 33%W/V | E12: EC | F12: Sinon Corporation Taiwan R.O.C.; Sinon Chemical (China) Co., Ltd. PRC | G12: ซิงหนง (ประเทศไทย) | H12: ซิงหนง (ประเทศไทย) | I12: ซิงหนง (ประเทศไทย) บจก. | J12: 08/09/2023 | K12: 07/09/2029 | L12: =IFERROR(_xlfn.XLOOKUP($C12,'Pesticide Types'!$A$2:$A$519,'Pesticide Types'!$B$2:$B$519),"Unclassified") -> Herbicide | M12: =IFERROR(_xlfn.XLOOKUP($C12,'Pesticide Types'!$A$2:$A$519,'Pesticide Types'!$D$2:$D$519),"None") -> HRAC 3
A13: 71 - 2554 | B13: อีโคแมกซ์ (ECOMAX) | C13: glyphosate-isopropylammonium | D13: 48%W/V | E13: SL | F13: CP Manufacturing Sdn Bhd., Malaysia | G13: คอร์ป โพรเทคชั่น อะโกร (ประเทศไทย) | H13: คอร์ปโพรเทคชั่น อะโกร (ปท) บจก | I13: คอร์ป โพรเทคชั่น อะโกร (ประเทศไทย) บจก. | J13: 08/09/2023 | K13: 07/09/2029 | L13: =IFERROR(_xlfn.XLOOKUP($C13,'Pesticide Types'!$A$2:$A$519,'Pesticide Types'!$B$2:$B$519),"Unclassified") -> Herbicide | M13: =IFERROR(_xlfn.XLOOKUP($C13,'Pesticide Types'!$A$2:$A$519,'Pesticide Types'!$D$2:$D$519),"None") -> HRAC 9
A14: 82 - 2554 | B14: นาติโว 75 ดับบลิวจี (Nativo 75 WG) | C14: trifloxystrobin+tebuconazole | D14: 25%+50% | E14: WG | F14: Bayer Vietnam Limited, Vietnam | G14: ไบเออร์ไทย บจก. | H14: ไบเออร์ไทย บจก. | I14: ไบเออร์ไทย บจก. | J14: 12/09/2023 | K14: 11/09/2029 | L14: =IFERROR(_xlfn.XLOOKUP($C14,'Pesticide Types'!$A$2:$A$519,'Pesticide Types'!$B$2:$B$519),"Unclassified") -> Unclassified | M14: =IFERROR(_xlfn.XLOOKUP($C14,'Pesticide Types'!$A$2:$A$519,'Pesticide Types'!$D$2:$D$519),"None") -> None
A15: 105 - 2554 | B15: เพลนั่ม 50 ดับบลิวจี (Plenum 50 WG) | C15: pymetrozine | D15: 0.5 | E15: WG | F15: Syngenta Korea Limited, Korea | G15: ซินเจนทา ครอป โปรเทคชั่น บจก. | H15: ซินเจนทา ครอป โปรเทคชั่น บจก. | I15: ซินเจนทา ครอป โปรเทคชั่น บจก. | J15: 30/09/2023 | K15: 29/09/2029 | L15: =IFERROR(_xlfn.XLOOKUP($C15,'Pesticide Types'!$A$2:$A$519,'Pesticide Types'!$B$2:$B$519),"Unclassified") -> Insecticide | M15: =IFERROR(_xlfn.XLOOKUP($C15,'Pesticide Types'!$A$2:$A$519,'Pesticide Types'!$D$2:$D$519),"None") -> IRAC 9B
A16: 110 - 2554 | B16: อิมิดาโคลพริด 70% ดับบลิวจี (Imidacloprid 70 % WG) | C16: imidacloprid | D16: 0.7 | E16: WG | F16: Jiangsu Kesheng Group Co., Ltd. PRC | G16: เอส แอนด์ พี ฟอร์มูเลเตอร์ บจก. | H16: เอส แอนด์ พี ฟอร์มูเลเตอร์ บจก. | I16: เอส แอนด์ พี ฟอร์มูเลเตอร์ บจก. | J16: 04/10/2023 | K16: 03/10/2029 | L16: =IFERROR(_xlfn.XLOOKUP($C16,'Pesticide Types'!$A$2:$A$519,'Pesticide Types'!$B$2:$B$519),"Unclassified") -> Insecticide | M16: =IFERROR(_xlfn.XLOOKUP($C16,'Pesticide Types'!$A$2:$A$519,'Pesticide Types'!$D$2:$D$519),"None") -> IRAC 4A
A17: 111 - 2554 | B17: แพนเทอร่า 40 อีซี | C17: quizalofop-p-tefuryl | D17: 4%W/V | E17: EC | F17: Chemark KFT, Hungary; Arysta LifeScience Ourgree Production sprl, Belgium; Arysta LifeSceience India Limited, India | G17: โซตัส อินเตอร์เนชั่นแนล บจก. | H17: โซตัส อินเตอร์เนชั่นแนล บจก. | I17: โซตัส อินเตอร์เนชั่นแนล บจก. | J17: 10/10/2023 | K17: 09/10/2029 | L17: =IFERROR(_xlfn.XLOOKUP($C17,'Pesticide Types'!$A$2:$A$519,'Pesticide Types'!$B$2:$B$519),"Unclassified") -> Herbicide | M17: =IFERROR(_xlfn.XLOOKUP($C17,'Pesticide Types'!$A$2:$A$519,'Pesticide Types'!$D$2:$D$519),"None") -> HRAC 1
A18: 114 - 2554 | B18: แพนเทอร่า 40 อีซี (Pantera 40 EC) | C18: quizalofop-p-tefuryl | D18: 4%W/V | E18: EC | F18: Arysta LufeScience Ougree Production sprl, Belgium; Arysta LufeScience India Limited, India | G18: โซตัส อินเตอร์เนชั่นแนล บจก. | H18: โซตัส อินเตอร์เนชั่นแนล บจก. | I18: โซตัส อินเตอร์เนชั่นแนล บจก. | J18: 10/10/2023 | K18: 09/10/2029 | L18: =IFERROR(_xlfn.XLOOKUP($C18,'Pesticide Types'!$A$2:$A$519,'Pesticide Types'!$B$2:$B$519),"Unclassified") -> Herbicide | M18: =IFERROR(_xlfn.XLOOKUP($C18,'Pesticide Types'!$A$2:$A$519,'Pesticide Types'!$D$2:$D$519),"None") -> HRAC 1
A19: 137 - 2554 | B19: ไดฟีโนโคนาโซล เทค (Difenoconazole Tech) | C19: difenoconazole | D19: 94%min. | E19: Tech. | F19: Syngenta Crop Protection Monthey SA., Switzerland; Deccan Fine Chemicals (india) Private Limited, India; Youjia Crop Protection Co.,Ltd.PRC | G19: ซินเจนทา ครอป โปรเทคชั่น บจก. | H19: ซินเจนทา ครอป โปรเทคชั่น บจก. | I19: ซินเจนทา ครอป โปรเทคชั่น บจก. | J19: 18/10/2023 | K19: 17/10/2029 | L19: =IFERROR(_xlfn.XLOOKUP($C19,'Pesticide Types'!$A$2:$A$519,'Pesticide Types'!$B$2:$B$519),"Unclassified") -> Fungicide | M19: =IFERROR(_xlfn.XLOOKUP($C19,'Pesticide Types'!$A$2:$A$519,'Pesticide Types'!$D$2:$D$519),"None") -> FRAC 3
A20: 138 - 2554 | B20: โพรพิโคลนาโซล เทค (Propiconazole Tech) | C20: propiconazole | D20: 94%min. | E20: Tech. | F20: Syngenta Crop Protection Monthey AG., Switzerland; NACL Industries Limited, India; Youjia Crop Protection Co., Ltd. PRC | G20: ซินเจนทา ครอป โปรเทคชั่น บจก. | H20: ซินเจนทา ครอป โปรเทคชั่น บจก. | I20: ซินเจนทา ครอป โปรเทคชั่น บจก. | J20: 18/10/2023 | K20: 17/10/2029 | L20: =IFERROR(_xlfn.XLOOKUP($C20,'Pesticide Types'!$A$2:$A$519,'Pesticide Types'!$B$2:$B$519),"Unclassified") -> Fungicide | M20: =IFERROR(_xlfn.XLOOKUP($C20,'Pesticide Types'!$A$2:$A$519,'Pesticide Types'!$D$2:$D$519),"None") -> FRAC 3
A21: 140 - 2554 | B21: ฟังกูราน-โอเอช (Funguran-OH) | C21: copper hydroxide | D21: 0.77 | E21: WP | F21: Cosaco GmbH, Germany | G21: โซตัส อินเตอร์เนชั่นแนล บจก. | H21: โซตัส อินเตอร์เนชั่นแนล บจก. | I21: โซตัส อินเตอร์เนชั่นแนล บจก. | J21: 18/10/2023 | K21: 17/10/2029 | L21: =IFERROR(_xlfn.XLOOKUP($C21,'Pesticide Types'!$A$2:$A$519,'Pesticide Types'!$B$2:$B$519),"Unclassified") -> Fungicide | M21: =IFERROR(_xlfn.XLOOKUP($C21,'Pesticide Types'!$A$2:$A$519,'Pesticide Types'!$D$2:$D$519),"None") -> FRAC M01
A22: 143 - 2554 | B22: อะทราซีน 80% ดับเบิลยูพี (Atrazine 80 % WP) | C22: atrazine | D22: 0.8 | E22: WP | F22: Zhejiang Zhongshan Chemical Industry Group Co., Ltd. PRC | G22: ไอ ซี พี ลัดดา บจก. | H22: ไอ ซี พี ลัดดา บจก. | I22: ไอ ซี พี ลัดดา บจก. | J22: 18/10/2023 | K22: 17/10/2029 | L22: =IFERROR(_xlfn.XLOOKUP($C22,'Pesticide Types'!$A$2:$A$519,'Pesticide Types'!$B$2:$B$519),"Unclassified") -> Herbicide | M22: =IFERROR(_xlfn.XLOOKUP($C22,'Pesticide Types'!$A$2:$A$519,'Pesticide Types'!$D$2:$D$519),"None") -> HRAC 5
A23: 146 - 2554 | B23: เฟลกซ์ (Flex) | C23: fomesafen | D23: 25%W/V | E23: SL | F23: Jiangsu Changqing Biotechnology Co., Ltd. PRC | G23: ซินเจนทา ครอป โปรเทคชั่น บจก. | H23: ซินเจนทา ครอป โปรเทคชั่น บจก. | I23: ซินเจนทา ครอป โปรเทคชั่น บจก. | J23: 19/10/2023 | K23: 18/10/2029 | L23: =IFERROR(_xlfn.XLOOKUP($C23,'Pesticide Types'!$A$2:$A$519,'Pesticide Types'!$B$2:$B$519),"Unclassified") -> Herbicide | M23: =IFERROR(_xlfn.XLOOKUP($C23,'Pesticide Types'!$A$2:$A$519,'Pesticide Types'!$D$2:$D$519),"None") -> HRAC 14
A24: 147 - 2554 | B24: เฟลกซ์ | C24: fomesafen | D24: 25%W/V | E24: SL | F24: Jiangsu Changqing Biotechnology Co., Ltd. PRC | G24: ซินเจนทา ครอป โปรเทคชั่น บจก. | H24: ซินเจนทา ครอป โปรเทคชั่น บจก. | I24: ซินเจนทา ครอป โปรเทคชั่น บจก. | J24: 19/10/2023 | K24: 18/10/2029 | L24: =IFERROR(_xlfn.XLOOKUP($C24,'Pesticide Types'!$A$2:$A$519,'Pesticide Types'!$B$2:$B$519),"Unclassified") -> Herbicide | M24: =IFERROR(_xlfn.XLOOKUP($C24,'Pesticide Types'!$A$2:$A$519,'Pesticide Types'!$D$2:$D$519),"None") -> HRAC 14
A25: 148 - 2554 | B25: อามูเร่ (Armure) | C25: difenoconazole+propiconazole | D25: 15%+15%W/V | E25: EC | F25: PT Syngenta Indonesia, Indonesia | G25: ซินเจนทา ครอป โปรเทคชั่น บจก. | H25: ซินเจนทา ครอป โปรเทคชั่น บจก. | I25: ซินเจนทา ครอป โปรเทคชั่น บจก. | J25: 19/10/2023 | K25: 18/10/2029 | L25: =IFERROR(_xlfn.XLOOKUP($C25,'Pesticide Types'!$A$2:$A$519,'Pesticide Types'!$B$2:$B$519),"Unclassified") -> Unclassified | M25: =IFERROR(_xlfn.XLOOKUP($C25,'Pesticide Types'!$A$2:$A$519,'Pesticide Types'!$D$2:$D$519),"None") -> None
A26: 149 - 2554 | B26: บูโพรเฟซิน 40 เอสซี (Buprofezin 40 SC) | C26: buprofezin | D26: 40%W/V | E26: SC | F26: Jiangsu Changlong Agrochemicals Co., Ltd. PRC | G26: เมอริสเต็ม | H26: เมอริสเต็ม | I26: เวล อกริเทค บจก. | J26: 19/10/2023 | K26: 18/10/2029 | L26: =IFERROR(_xlfn.XLOOKUP($C26,'Pesticide Types'!$A$2:$A$519,'Pesticide Types'!$B$2:$B$519),"Unclassified") -> Insecticide | M26: =IFERROR(_xlfn.XLOOKUP($C26,'Pesticide Types'!$A$2:$A$519,'Pesticide Types'!$D$2:$D$519),"None") -> IRAC 16
A27: 150 - 2554 | B27: บูโพรเฟซิน 25 ดับลิวพี (Buprofezin 25 WP) | C27: buprofezin | D27: 0.25 | E27: WP | F27: Jiangsu Changlong Agrochemicals Co., Ltd. PRC | G27: เมอริสเต็ม | H27: เมอริสเต็ม | I27: เมอริสเต็ม บจก. | J27: 19/10/2023 | K27: 18/10/2029 | L27: =IFERROR(_xlfn.XLOOKUP($C27,'Pesticide Types'!$A$2:$A$519,'Pesticide Types'!$B$2:$B$519),"Unclassified") -> Insecticide | M27: =IFERROR(_xlfn.XLOOKUP($C27,'Pesticide Types'!$A$2:$A$519,'Pesticide Types'!$D$2:$D$519),"None") -> IRAC 16
A28: 151 - 2554 | B28: ดูอัล โกลด์ | C28: s-metolachlor | D28: 96%W/V | E28: EC | F28: Chemark ZRT., Hungary; Syngenta Production France S.A.S., France; Syngenta (Suzhou) Crop Protection Co., Ltd. PRC | G28: ซินเจนทา ครอป โปรเทคชั่น บจก. | H28: ซินเจนทา ครอป โปรเทคชั่น บจก. | I28: ซินเจนทา ครอป โปรเทคชั่น บจก. | J28: 19/10/2023 | K28: 18/10/2029 | L28: =IFERROR(_xlfn.XLOOKUP($C28,'Pesticide Types'!$A$2:$A$519,'Pesticide Types'!$B$2:$B$519),"Unclassified") -> Herbicide | M28: =IFERROR(_xlfn.XLOOKUP($C28,'Pesticide Types'!$A$2:$A$519,'Pesticide Types'!$D$2:$D$519),"None") -> HRAC 15
A29: 152 - 2554 | B29: อามูเร่ | C29: difenoconazole+propiconazole | D29: 15%+15%W/V | E29: EC | F29: PT Syngenta Indonesia, Indonesia | G29: ซินเจนทา ครอป โปรเทคชั่น บจก. | H29: ซินเจนทา ครอป โปรเทคชั่น บจก. | I29: ซินเจนทา ครอป โปรเทคชั่น บจก. | J29: 19/10/2023 | K29: 18/10/2029 | L29: =IFERROR(_xlfn.XLOOKUP($C29,'Pesticide Types'!$A$2:$A$519,'Pesticide Types'!$B$2:$B$519),"Unclassified") -> Unclassified | M29: =IFERROR(_xlfn.XLOOKUP($C29,'Pesticide Types'!$A$2:$A$519,'Pesticide Types'!$D$2:$D$519),"None") -> None
A30: 157 - 2554 | B30: สกอร์ (Score) | C30: difenoconazole | D30: 25%W/V | E30: EC | F30: PT Syngenta Indonesia, Indonesia | G30: ซินเจนทา ครอป โปรเทคชั่น บจก. | H30: ซินเจนทา ครอป โปรเทคชั่น บจก. | I30: ซินเจนทา ครอป โปรเทคชั่น บจก. | J30: 19/10/2023 | K30: 18/10/2029 | L30: =IFERROR(_xlfn.XLOOKUP($C30,'Pesticide Types'!$A$2:$A$519,'Pesticide Types'!$B$2:$B$519),"Unclassified") -> Fungicide | M30: =IFERROR(_xlfn.XLOOKUP($C30,'Pesticide Types'!$A$2:$A$519,'Pesticide Types'!$D$2:$D$519),"None") -> FRAC 3
A31: 158 - 2554 | B31: ราวด์อั้พ (Roundup) | C31: glyphosate-isopropylammonium | D31: 48%W/V | E31: SL | F31: Monsanto Malaysia Sdn., Bhd. Malaysia | G31: มอนซานโต้ ไทยแลนด์ | H31: มอนซานโต้ ไทยแลนด์ | I31: มอนซานโต้ ไทยแลนด์ บจก. | J31: 19/10/2023 | K31: 18/10/2029 | L31: =IFERROR(_xlfn.XLOOKUP($C31,'Pesticide Types'!$A$2:$A$519,'Pesticide Types'!$B$2:$B$519),"Unclassified") -> Herbicide | M31: =IFERROR(_xlfn.XLOOKUP($C31,'Pesticide Types'!$A$2:$A$519,'Pesticide Types'!$D$2:$D$519),"None") -> HRAC 9
A32: 171 - 2554 | B32: โซลิโต้ (Solito) | C32: pretilachlor+pyribenzoxim | D32: 30%+2%W/V | E32: EC | F32: Asiatic Agricultural Industries Pte., Ltd., Singapore; Syngenta Vietnam Ltd., Vietnam | G32: ซินเจนทา ครอป โปรเทคชั่น บจก. | H32: ซินเจนทา ครอป โปรเทคชั่น บจก. | I32: ซินเจนทา ครอป โปรเทคชั่น บจก. | J32: 25/10/2023 | K32: 24/10/2029 | L32: =IFERROR(_xlfn.XLOOKUP($C32,'Pesticide Types'!$A$2:$A$519,'Pesticide Types'!$B$2:$B$519),"Unclassified") -> Unclassified | M32: =IFERROR(_xlfn.XLOOKUP($C32,'Pesticide Types'!$A$2:$A$519,'Pesticide Types'!$D$2:$D$519),"None") -> None
A33: 172 - 2554 | B33: แอคทารา 25 ดับบลิวจี (Actara 25 WG) | C33: thiamethoxam | D33: 0.25 | E33: WG | F33: Syngenta India Private Limited, India; Deccan Fine Chemicals (India) Private Limited, India; Syngenta Korea Limited, Republic of Korea | G33: ซินเจนทา ครอป โปรเทคชั่น บจก. | H33: ซินเจนทา ครอป โปรเทคชั่น บจก. | I33: ซินเจนทา ครอป โปรเทคชั่น บจก. | J33: 25/10/2023 | K33: 24/10/2029 | L33: =IFERROR(_xlfn.XLOOKUP($C33,'Pesticide Types'!$A$2:$A$519,'Pesticide Types'!$B$2:$B$519),"Unclassified") -> Insecticide | M33: =IFERROR(_xlfn.XLOOKUP($C33,'Pesticide Types'!$A$2:$A$519,'Pesticide Types'!$D$2:$D$519),"None") -> IRAC 4A
A34: 173 - 2554 | B34: เวอตาโก 40 ดับบลิวจี (Virtako 40 WG) | C34: chlorantraniliprole+thiamethoxam | D34: 20%+20% | E34: WG | F34: Gowan Milling, USA; Syngenta Nantong Crop Protection Co., Ltd. PRC | G34: ซินเจนทา ครอป โปรเทคชั่น บจก. | H34: ซินเจนทา ครอป โปรเทคชั่น บจก. | I34: ซินเจนทา ครอป โปรเทคชั่น บจก. | J34: 25/10/2023 | K34: 24/10/2029 | L34: =IFERROR(_xlfn.XLOOKUP($C34,'Pesticide Types'!$A$2:$A$519,'Pesticide Types'!$B$2:$B$519),"Unclassified") -> Unclassified | M34: =IFERROR(_xlfn.XLOOKUP($C34,'Pesticide Types'!$A$2:$A$519,'Pesticide Types'!$D$2:$D$519),"None") -> None
A35: 178 - 2554 | B35: อะมีทรีน 80% ดับบลิวพี (Ametryn 80% WP) | C35: ametryn | D35: 0.8 | E35: WP | F35: Zhejiang Zhongshan Chemical Industry Group Co., Ltd. PRC | G35: เอราวัณ เคมีเกษตร บจก. | H35: เอราวัณ เคมีเกษตร บจก. | I35: เอราวัณ เคมีเกษตร บจก. | J35: 11/11/2023 | K35: 10/11/2029 | L35: =IFERROR(_xlfn.XLOOKUP($C35,'Pesticide Types'!$A$2:$A$519,'Pesticide Types'!$B$2:$B$519),"Unclassified") -> Herbicide | M35: =IFERROR(_xlfn.XLOOKUP($C35,'Pesticide Types'!$A$2:$A$519,'Pesticide Types'!$D$2:$D$519),"None") -> HRAC 5
A36: 180 - 2554 | B36: โคลมาโซน 48% อีซี (Clomazone 48 % EC) | C36: clomazone | D36: 48%W/V | E36: EC | F36: Jiangsu Jiannong ABA Agrochemical Co., Ltd., PRC | G36: โกลบอล ครอปส์ บจก. | H36: โกลบอล ครอปส์ บจก. | I36: โกลบอล ครอปส์ บจก. | J36: 14/11/2023 | K36: 13/11/2029 | L36: =IFERROR(_xlfn.XLOOKUP($C36,'Pesticide Types'!$A$2:$A$519,'Pesticide Types'!$B$2:$B$519),"Unclassified") -> Herbicide | M36: =IFERROR(_xlfn.XLOOKUP($C36,'Pesticide Types'!$A$2:$A$519,'Pesticide Types'!$D$2:$D$519),"None") -> HRAC 13
A37: 181 - 2554 | B37: โกลเซ็น (Glozen) | C37: butachlor | D37: 60%W/V | E37: EW | F37: Shandong Binnong Technology Co., Ltd. PRC | G37: โกลบอล ครอปส์ บจก. | H37: โกลบอล ครอปส์ บจก. | I37: โกลบอล ครอปส์ บจก. | J37: 14/11/2023 | K37: 13/11/2029 | L37: =IFERROR(_xlfn.XLOOKUP($C37,'Pesticide Types'!$A$2:$A$519,'Pesticide Types'!$B$2:$B$519),"Unclassified") -> Herbicide | M37: =IFERROR(_xlfn.XLOOKUP($C37,'Pesticide Types'!$A$2:$A$519,'Pesticide Types'!$D$2:$D$519),"None") -> HRAC 15
A38: 184 - 2554 | B38: สปาย (Spy) | C38: bispyribac-sodium | D38: 0.2 | E38: WP | F38: Jiangsu Institute of Ecomones Co., Ltd. PRC | G38: ซัน อโกรเทค | H38: ซัน อโกรเทค | I38: ซัน อโกรเทค บจก. | J38: 15/11/2023 | K38: 14/11/2029 | L38: =IFERROR(_xlfn.XLOOKUP($C38,'Pesticide Types'!$A$2:$A$519,'Pesticide Types'!$B$2:$B$519),"Unclassified") -> Herbicide | M38: =IFERROR(_xlfn.XLOOKUP($C38,'Pesticide Types'!$A$2:$A$519,'Pesticide Types'!$D$2:$D$519),"None") -> HRAC 2
A39: 187 - 2554 | B39: บาซิน่า (Bacina) | C39: bacillus thuringiensis subsp. aizawai | D39: 3.70 x 109 cfu/g [32,000 IU/mg (4%WP)] | E39: WP | F39: King Biotec Corp Co., Ltd. PRC | G39: ไอ ซี พี ลัดดา บจก. | H39: ไอ ซี พี ลัดดา บจก. | I39: ไอ ซี พี ลัดดา บจก. | J39: 15/11/2023 | K39: 14/11/2029 | L39: =IFERROR(_xlfn.XLOOKUP($C39,'Pesticide Types'!$A$2:$A$519,'Pesticide Types'!$B$2:$B$519),"Unclassified") -> Insecticide | M39: =IFERROR(_xlfn.XLOOKUP($C39,'Pesticide Types'!$A$2:$A$519,'Pesticide Types'!$D$2:$D$519),"None") -> IRAC 11A
A40: 188 - 2554 | B40: โคลมาโซน 48 อีซี (Clomazone 480 EC) | C40: clomazone | D40: 48%W/V | E40: EC | F40: Jiangsu Heben Biochemical Co., Ltd. PRC | G40: ไอ ซี พี ลัดดา บจก. | H40: ไอ ซี พี ลัดดา บจก. | I40: ไอ ซี พี ลัดดา บจก. | J40: 15/11/2023 | K40: 14/11/2029 | L40: =IFERROR(_xlfn.XLOOKUP($C40,'Pesticide Types'!$A$2:$A$519,'Pesticide Types'!$B$2:$B$519),"Unclassified") -> Herbicide | M40: =IFERROR(_xlfn.XLOOKUP($C40,'Pesticide Types'!$A$2:$A$519,'Pesticide Types'!$D$2:$D$519),"None") -> HRAC 13
...

Sheet Pesticide Types
A1: Active Ingredient (common_name) | B1: Pesticide Type | C1: Rows in Registration | D1: MoA Group (HRAC/IRAC/FRAC)
A2: imidacloprid | B2: Insecticide | C2: 485 | D2: IRAC 4A
A3: glufosinate-ammonium | B3: Herbicide | C3: 483 | D3: HRAC 10
A4: emamectin benzoate | B4: Insecticide | C4: 482 | D4: IRAC 6
A5: glyphosate-isopropylammonium | B5: Herbicide | C5: 463 | D5: HRAC 9
A6: fipronil | B6: Insecticide | C6: 440 | D6: IRAC 2B
A7: butachlor | B7: Herbicide | C7: 401 | D7: HRAC 15
A8: abamectin | B8: Insecticide | C8: 382 | D8: IRAC 6
A9: ametryn | B9: Herbicide | C9: 364 | D9: HRAC 5
A10: atrazine | B10: Herbicide | C10: 361 | D10: HRAC 5
A11: carbendazim | B11: Fungicide | C11: 340 | D11: FRAC 1
A12: diuron | B12: Herbicide | C12: 325 | D12: HRAC 5
A13: bispyribac-sodium | B13: Herbicide | C13: 322 | D13: HRAC 2
... A519: flufenacet + metribuzin | B519: Herbicide | C519: 1 | D519: HRAC 15 + 5
